在 C# 中，`catch (Exception ex)` 和 `catch (System.Threading.ThreadAbortException ex)` 主要有以下幾個差異：

---

### 1. **異常類型範圍**
- `catch (Exception ex)`:  
  - 捕捉 **所有** 繼承自 `System.Exception` 的異常（包含 `ThreadAbortException`）。
  - 這是最通用的異常處理方式，但有時可能會不小心吞掉某些應該特別處理的異常。

- `catch (System.Threading.ThreadAbortException ex)`:  
  - 只捕捉 `ThreadAbortException`，這是一種特殊的異常，當執行 `Thread.Abort()` 時拋出。
  - `ThreadAbortException` 會在 `catch` 區塊執行完畢後，**再次被拋出**，除非你在 `catch` 區塊中使用 `Thread.ResetAbort()` 來阻止。

---

### 2. **`ThreadAbortException` 的特殊行為**
當 `Thread.Abort()` 被呼叫時：
- **一般異常 (`Exception`)** 會被 `catch` 捕獲並正常處理。
- **`ThreadAbortException`** 具有特殊的行為：
  1. 它會立即中斷執行緒的執行。
  2. 即使被 `catch` 捕獲，當 `catch` 區塊執行完畢後，該異常 **仍會再次拋出**（除非使用 `Thread.ResetAbort()`）。

示例：
```csharp
try
{
    Thread.CurrentThread.Abort(); // 強制中止當前執行緒
}
catch (ThreadAbortException ex)
{
    Console.WriteLine("ThreadAbortException 被捕獲，但仍會被重新拋出");
    // Thread.ResetAbort();  // 若取消註解，則執行緒不會被中止
}
catch (Exception ex)
{
    Console.WriteLine("一般異常處理: " + ex.Message);
}
finally
{
    Console.WriteLine("Finally 區塊仍然會執行");
}
Console.WriteLine("程式是否能執行到這裡？");
```
### **輸出**
```
ThreadAbortException 被捕獲，但仍會被重新拋出
Finally 區塊仍然會執行
```
（接著執行緒終止，`Console.WriteLine("程式是否能執行到這裡？");` 不會執行。）

如果在 `catch (ThreadAbortException ex)` 內部執行 `Thread.ResetAbort();`，則執行緒不會終止。

---

### 3. **最佳實踐**
- **避免在 `catch (Exception ex)` 中捕捉 `ThreadAbortException`**，因為它會讓 `Thread.Abort()` 無法正常終止執行緒。
- **如果有必要捕獲 `ThreadAbortException`**，應該專門使用 `catch (ThreadAbortException ex)` 來處理，並決定是否執行 `Thread.ResetAbort()`。
- **建議使用 `catch (Exception ex) when (!(ex is ThreadAbortException))`** 來避免誤捕 `ThreadAbortException`：
  ```csharp
  catch (Exception ex) when (!(ex is ThreadAbortException))
  {
      Console.WriteLine("捕捉所有異常（但不包含 ThreadAbortException）");
  }
  ```

---

### **結論**
|  比較項目  | `catch (Exception ex)` | `catch (ThreadAbortException ex)` |
|------------|-----------------------|-----------------------------------|
| 捕捉範圍 | 捕獲所有異常（包含 `ThreadAbortException`） | 只捕獲 `ThreadAbortException` |
| `ThreadAbortException` 影響 | 捕獲後仍會再次拋出 | 捕獲後仍會再次拋出（可用 `Thread.ResetAbort()` 取消中止） |
| 使用場景 | 一般異常處理 | 特別處理 `Thread.Abort()` |

🔹 **如果需要特別處理 `ThreadAbortException`，應該單獨使用 `catch (ThreadAbortException ex)`，而不是讓它進入 `catch (Exception ex)`。**